[2023-05-24 21:43:40,221] {taskinstance.py:896} INFO - Dependencies all met for <TaskInstance: python_square_operator.square 2023-05-24T21:43:38.018927+00:00 [queued]>
[2023-05-24 21:43:40,262] {taskinstance.py:896} INFO - Dependencies all met for <TaskInstance: python_square_operator.square 2023-05-24T21:43:38.018927+00:00 [queued]>
[2023-05-24 21:43:40,264] {taskinstance.py:1087} INFO - 
--------------------------------------------------------------------------------
[2023-05-24 21:43:40,265] {taskinstance.py:1088} INFO - Starting attempt 1 of 1
[2023-05-24 21:43:40,267] {taskinstance.py:1089} INFO - 
--------------------------------------------------------------------------------
[2023-05-24 21:43:40,306] {taskinstance.py:1107} INFO - Executing <Task(PythonOperator): square> on 2023-05-24T21:43:38.018927+00:00
[2023-05-24 21:43:40,314] {standard_task_runner.py:52} INFO - Started process 1230 to run task
[2023-05-24 21:43:40,343] {standard_task_runner.py:76} INFO - Running: ['***', 'tasks', 'run', 'python_square_operator', 'square', '2023-05-24T21:43:38.018927+00:00', '--job-id', '3', '--pool', 'default_pool', '--raw', '--subdir', 'DAGS_FOLDER/module19_assignment.py', '--cfg-path', '/tmp/tmpk3sgz3pt', '--error-file', '/tmp/tmpxlwaytxn']
[2023-05-24 21:43:40,347] {standard_task_runner.py:77} INFO - Job 3: Subtask square
[2023-05-24 21:43:40,519] {logging_mixin.py:104} INFO - Running <TaskInstance: python_square_operator.square 2023-05-24T21:43:38.018927+00:00 [running]> on host f66eba1d7275
[2023-05-24 21:43:40,652] {taskinstance.py:1302} INFO - Exporting the following env vars:
AIRFLOW_CTX_DAG_OWNER=***
AIRFLOW_CTX_DAG_ID=python_square_operator
AIRFLOW_CTX_TASK_ID=square
AIRFLOW_CTX_EXECUTION_DATE=2023-05-24T21:43:38.018927+00:00
AIRFLOW_CTX_DAG_RUN_ID=manual__2023-05-24T21:43:38.018927+00:00
[2023-05-24 21:43:40,656] {taskinstance.py:1501} ERROR - Task failed with exception
Traceback (most recent call last):
  File "/home/airflow/.local/lib/python3.6/site-packages/airflow/models/taskinstance.py", line 1157, in _run_raw_task
    self._prepare_and_execute_task_with_callbacks(context, task)
  File "/home/airflow/.local/lib/python3.6/site-packages/airflow/models/taskinstance.py", line 1331, in _prepare_and_execute_task_with_callbacks
    result = self._execute_task(context, task_copy)
  File "/home/airflow/.local/lib/python3.6/site-packages/airflow/models/taskinstance.py", line 1361, in _execute_task
    result = task_copy.execute(context=context)
  File "/home/airflow/.local/lib/python3.6/site-packages/airflow/operators/python.py", line 150, in execute
    return_value = self.execute_callable()
  File "/home/airflow/.local/lib/python3.6/site-packages/airflow/operators/python.py", line 161, in execute_callable
    return self.python_callable(*self.op_args, **self.op_kwargs)
TypeError: square() missing 1 required positional argument: 'x'
[2023-05-24 21:43:40,665] {taskinstance.py:1551} INFO - Marking task as FAILED. dag_id=python_square_operator, task_id=square, execution_date=20230524T214338, start_date=20230524T214340, end_date=20230524T214340
[2023-05-24 21:43:40,722] {local_task_job.py:151} INFO - Task exited with return code 1
