[2023-05-24 21:48:07,637] {taskinstance.py:896} INFO - Dependencies all met for <TaskInstance: python_square_operator.square 2023-05-24T21:48:05.809318+00:00 [queued]>
[2023-05-24 21:48:07,666] {taskinstance.py:896} INFO - Dependencies all met for <TaskInstance: python_square_operator.square 2023-05-24T21:48:05.809318+00:00 [queued]>
[2023-05-24 21:48:07,667] {taskinstance.py:1087} INFO - 
--------------------------------------------------------------------------------
[2023-05-24 21:48:07,668] {taskinstance.py:1088} INFO - Starting attempt 1 of 1
[2023-05-24 21:48:07,669] {taskinstance.py:1089} INFO - 
--------------------------------------------------------------------------------
[2023-05-24 21:48:07,697] {taskinstance.py:1107} INFO - Executing <Task(PythonOperator): square> on 2023-05-24T21:48:05.809318+00:00
[2023-05-24 21:48:07,703] {standard_task_runner.py:52} INFO - Started process 1527 to run task
[2023-05-24 21:48:07,711] {standard_task_runner.py:76} INFO - Running: ['***', 'tasks', 'run', 'python_square_operator', 'square', '2023-05-24T21:48:05.809318+00:00', '--job-id', '5', '--pool', 'default_pool', '--raw', '--subdir', 'DAGS_FOLDER/module19_assignment.py', '--cfg-path', '/tmp/tmpxd9o8dyt', '--error-file', '/tmp/tmpyx1k_uhr']
[2023-05-24 21:48:07,713] {standard_task_runner.py:77} INFO - Job 5: Subtask square
[2023-05-24 21:48:07,793] {logging_mixin.py:104} INFO - Running <TaskInstance: python_square_operator.square 2023-05-24T21:48:05.809318+00:00 [running]> on host f66eba1d7275
[2023-05-24 21:48:07,891] {taskinstance.py:1302} INFO - Exporting the following env vars:
AIRFLOW_CTX_DAG_OWNER=***
AIRFLOW_CTX_DAG_ID=python_square_operator
AIRFLOW_CTX_TASK_ID=square
AIRFLOW_CTX_EXECUTION_DATE=2023-05-24T21:48:05.809318+00:00
AIRFLOW_CTX_DAG_RUN_ID=manual__2023-05-24T21:48:05.809318+00:00
[2023-05-24 21:48:07,894] {taskinstance.py:1501} ERROR - Task failed with exception
Traceback (most recent call last):
  File "/home/airflow/.local/lib/python3.6/site-packages/airflow/models/taskinstance.py", line 1157, in _run_raw_task
    self._prepare_and_execute_task_with_callbacks(context, task)
  File "/home/airflow/.local/lib/python3.6/site-packages/airflow/models/taskinstance.py", line 1331, in _prepare_and_execute_task_with_callbacks
    result = self._execute_task(context, task_copy)
  File "/home/airflow/.local/lib/python3.6/site-packages/airflow/models/taskinstance.py", line 1361, in _execute_task
    result = task_copy.execute(context=context)
  File "/home/airflow/.local/lib/python3.6/site-packages/airflow/operators/python.py", line 145, in execute
    context.update(self.op_kwargs)
ValueError: dictionary update sequence element #0 has length 1; 2 is required
[2023-05-24 21:48:07,901] {taskinstance.py:1551} INFO - Marking task as FAILED. dag_id=python_square_operator, task_id=square, execution_date=20230524T214805, start_date=20230524T214807, end_date=20230524T214807
[2023-05-24 21:48:07,970] {local_task_job.py:151} INFO - Task exited with return code 1
