[2023-06-23 21:00:16,727] {taskinstance.py:896} INFO - Dependencies all met for <TaskInstance: assignment.task_zero 2023-06-22T00:00:00+00:00 [queued]>
[2023-06-23 21:00:16,795] {taskinstance.py:896} INFO - Dependencies all met for <TaskInstance: assignment.task_zero 2023-06-22T00:00:00+00:00 [queued]>
[2023-06-23 21:00:16,798] {taskinstance.py:1087} INFO - 
--------------------------------------------------------------------------------
[2023-06-23 21:00:16,800] {taskinstance.py:1088} INFO - Starting attempt 1 of 3
[2023-06-23 21:00:16,802] {taskinstance.py:1089} INFO - 
--------------------------------------------------------------------------------
[2023-06-23 21:00:16,860] {taskinstance.py:1107} INFO - Executing <Task(BashOperator): task_zero> on 2023-06-22T00:00:00+00:00
[2023-06-23 21:00:16,870] {standard_task_runner.py:52} INFO - Started process 1843 to run task
[2023-06-23 21:00:16,889] {standard_task_runner.py:76} INFO - Running: ['***', 'tasks', 'run', 'assignment', 'task_zero', '2023-06-22T00:00:00+00:00', '--job-id', '8', '--pool', 'default_pool', '--raw', '--subdir', 'DAGS_FOLDER/assignment.py', '--cfg-path', '/tmp/tmptfb5rl6f', '--error-file', '/tmp/tmpn59wnqkm']
[2023-06-23 21:00:16,892] {standard_task_runner.py:77} INFO - Job 8: Subtask task_zero
[2023-06-23 21:00:17,106] {logging_mixin.py:104} INFO - Running <TaskInstance: assignment.task_zero 2023-06-22T00:00:00+00:00 [running]> on host 7f7a4865b07a
[2023-06-23 21:00:17,305] {taskinstance.py:1302} INFO - Exporting the following env vars:
AIRFLOW_CTX_DAG_OWNER=***
AIRFLOW_CTX_DAG_ID=assignment
AIRFLOW_CTX_TASK_ID=task_zero
AIRFLOW_CTX_EXECUTION_DATE=2023-06-22T00:00:00+00:00
AIRFLOW_CTX_DAG_RUN_ID=scheduled__2023-06-22T00:00:00+00:00
[2023-06-23 21:00:17,312] {subprocess.py:52} INFO - Tmp dir root location: 
 /tmp
[2023-06-23 21:00:17,315] {subprocess.py:63} INFO - Running command: ['bash', '-c', 'pip install beautifulsoup4']
[2023-06-23 21:00:17,341] {subprocess.py:75} INFO - Output:
[2023-06-23 21:00:27,953] {subprocess.py:79} INFO - Defaulting to user installation because normal site-packages is not writeable
[2023-06-23 21:00:28,992] {subprocess.py:79} INFO - Requirement already satisfied: beautifulsoup4 in /home/***/.local/lib/python3.6/site-packages (4.12.2)
[2023-06-23 21:00:29,050] {subprocess.py:79} INFO - Requirement already satisfied: soupsieve>1.2 in /home/***/.local/lib/python3.6/site-packages (from beautifulsoup4) (2.3.2.post1)
[2023-06-23 21:01:27,773] {subprocess.py:83} INFO - Command exited with return code 0
[2023-06-23 21:01:27,901] {taskinstance.py:1211} INFO - Marking task as SUCCESS. dag_id=assignment, task_id=task_zero, execution_date=20230622T000000, start_date=20230623T210016, end_date=20230623T210127
[2023-06-23 21:01:28,042] {taskinstance.py:1265} INFO - 1 downstream tasks scheduled from follow-on schedule check
[2023-06-23 21:01:28,110] {local_task_job.py:151} INFO - Task exited with return code 0
[2023-06-23 21:30:29,516] {taskinstance.py:896} INFO - Dependencies all met for <TaskInstance: assignment.task_zero 2023-06-22T00:00:00+00:00 [queued]>
[2023-06-23 21:30:29,580] {taskinstance.py:896} INFO - Dependencies all met for <TaskInstance: assignment.task_zero 2023-06-22T00:00:00+00:00 [queued]>
[2023-06-23 21:30:29,582] {taskinstance.py:1087} INFO - 
--------------------------------------------------------------------------------
[2023-06-23 21:30:29,584] {taskinstance.py:1088} INFO - Starting attempt 1 of 3
[2023-06-23 21:30:29,586] {taskinstance.py:1089} INFO - 
--------------------------------------------------------------------------------
[2023-06-23 21:30:29,642] {taskinstance.py:1107} INFO - Executing <Task(BashOperator): task_zero> on 2023-06-22T00:00:00+00:00
[2023-06-23 21:30:29,652] {standard_task_runner.py:52} INFO - Started process 4100 to run task
[2023-06-23 21:30:29,670] {standard_task_runner.py:76} INFO - Running: ['***', 'tasks', 'run', 'assignment', 'task_zero', '2023-06-22T00:00:00+00:00', '--job-id', '12', '--pool', 'default_pool', '--raw', '--subdir', 'DAGS_FOLDER/assignment.py', '--cfg-path', '/tmp/tmpzz0xgbd7', '--error-file', '/tmp/tmp4bpm43xk']
[2023-06-23 21:30:29,675] {standard_task_runner.py:77} INFO - Job 12: Subtask task_zero
[2023-06-23 21:30:29,852] {logging_mixin.py:104} INFO - Running <TaskInstance: assignment.task_zero 2023-06-22T00:00:00+00:00 [running]> on host 7f7a4865b07a
[2023-06-23 21:30:30,048] {taskinstance.py:1302} INFO - Exporting the following env vars:
AIRFLOW_CTX_DAG_OWNER=***
AIRFLOW_CTX_DAG_ID=assignment
AIRFLOW_CTX_TASK_ID=task_zero
AIRFLOW_CTX_EXECUTION_DATE=2023-06-22T00:00:00+00:00
AIRFLOW_CTX_DAG_RUN_ID=scheduled__2023-06-22T00:00:00+00:00
[2023-06-23 21:30:30,054] {subprocess.py:52} INFO - Tmp dir root location: 
 /tmp
[2023-06-23 21:30:30,057] {subprocess.py:63} INFO - Running command: ['bash', '-c', 'pip install beautifulsoup4']
[2023-06-23 21:30:30,083] {subprocess.py:75} INFO - Output:
[2023-06-23 21:37:42,274] {local_task_job.py:199} WARNING - State of this instance has been externally set to up_for_retry. Terminating instance.
[2023-06-23 21:37:42,298] {process_utils.py:100} INFO - Sending Signals.SIGTERM to GPID 4100
[2023-06-23 21:37:42,303] {taskinstance.py:1284} ERROR - Received SIGTERM. Terminating subprocesses.
[2023-06-23 21:37:42,307] {subprocess.py:89} INFO - Sending SIGTERM signal to process group
[2023-06-23 21:37:42,372] {taskinstance.py:1501} ERROR - Task failed with exception
Traceback (most recent call last):
  File "/home/airflow/.local/lib/python3.6/site-packages/airflow/models/taskinstance.py", line 1157, in _run_raw_task
    self._prepare_and_execute_task_with_callbacks(context, task)
  File "/home/airflow/.local/lib/python3.6/site-packages/airflow/models/taskinstance.py", line 1331, in _prepare_and_execute_task_with_callbacks
    result = self._execute_task(context, task_copy)
  File "/home/airflow/.local/lib/python3.6/site-packages/airflow/models/taskinstance.py", line 1361, in _execute_task
    result = task_copy.execute(context=context)
  File "/home/airflow/.local/lib/python3.6/site-packages/airflow/operators/bash.py", line 175, in execute
    output_encoding=self.output_encoding,
  File "/home/airflow/.local/lib/python3.6/site-packages/airflow/hooks/subprocess.py", line 77, in run_command
    for raw_line in iter(self.sub_process.stdout.readline, b''):
  File "/home/airflow/.local/lib/python3.6/site-packages/airflow/models/taskinstance.py", line 1286, in signal_handler
    raise AirflowException("Task received SIGTERM signal")
airflow.exceptions.AirflowException: Task received SIGTERM signal
[2023-06-23 21:37:42,401] {taskinstance.py:1551} INFO - Marking task as UP_FOR_RETRY. dag_id=assignment, task_id=task_zero, execution_date=20230622T000000, start_date=20230623T213029, end_date=20230623T213742
[2023-06-23 21:37:42,527] {process_utils.py:66} INFO - Process psutil.Process(pid=4100, status='terminated', exitcode=1, started='21:30:29') (4100) terminated with exit code 1
[2023-06-23 21:37:42,534] {process_utils.py:66} INFO - Process psutil.Process(pid=4102, status='terminated', started='21:30:29') (4102) terminated with exit code None
