[2023-05-24 21:43:38,997] {taskinstance.py:896} INFO - Dependencies all met for <TaskInstance: python_square_operator.square 2023-05-23T12:00:00+00:00 [queued]>
[2023-05-24 21:43:39,093] {taskinstance.py:896} INFO - Dependencies all met for <TaskInstance: python_square_operator.square 2023-05-23T12:00:00+00:00 [queued]>
[2023-05-24 21:43:39,097] {taskinstance.py:1087} INFO - 
--------------------------------------------------------------------------------
[2023-05-24 21:43:39,098] {taskinstance.py:1088} INFO - Starting attempt 1 of 1
[2023-05-24 21:43:39,099] {taskinstance.py:1089} INFO - 
--------------------------------------------------------------------------------
[2023-05-24 21:43:39,181] {taskinstance.py:1107} INFO - Executing <Task(PythonOperator): square> on 2023-05-23T12:00:00+00:00
[2023-05-24 21:43:39,211] {standard_task_runner.py:76} INFO - Running: ['***', 'tasks', 'run', 'python_square_operator', 'square', '2023-05-23T12:00:00+00:00', '--job-id', '2', '--pool', 'default_pool', '--raw', '--subdir', 'DAGS_FOLDER/module19_assignment.py', '--cfg-path', '/tmp/tmpee2jrrk4', '--error-file', '/tmp/tmpd5zyc8hh']
[2023-05-24 21:43:39,214] {standard_task_runner.py:77} INFO - Job 2: Subtask square
[2023-05-24 21:43:39,194] {standard_task_runner.py:52} INFO - Started process 1228 to run task
[2023-05-24 21:43:39,390] {logging_mixin.py:104} INFO - Running <TaskInstance: python_square_operator.square 2023-05-23T12:00:00+00:00 [running]> on host f66eba1d7275
[2023-05-24 21:43:39,522] {taskinstance.py:1302} INFO - Exporting the following env vars:
AIRFLOW_CTX_DAG_OWNER=***
AIRFLOW_CTX_DAG_ID=python_square_operator
AIRFLOW_CTX_TASK_ID=square
AIRFLOW_CTX_EXECUTION_DATE=2023-05-23T12:00:00+00:00
AIRFLOW_CTX_DAG_RUN_ID=scheduled__2023-05-23T12:00:00+00:00
[2023-05-24 21:43:39,526] {taskinstance.py:1501} ERROR - Task failed with exception
Traceback (most recent call last):
  File "/home/airflow/.local/lib/python3.6/site-packages/airflow/models/taskinstance.py", line 1157, in _run_raw_task
    self._prepare_and_execute_task_with_callbacks(context, task)
  File "/home/airflow/.local/lib/python3.6/site-packages/airflow/models/taskinstance.py", line 1331, in _prepare_and_execute_task_with_callbacks
    result = self._execute_task(context, task_copy)
  File "/home/airflow/.local/lib/python3.6/site-packages/airflow/models/taskinstance.py", line 1361, in _execute_task
    result = task_copy.execute(context=context)
  File "/home/airflow/.local/lib/python3.6/site-packages/airflow/operators/python.py", line 150, in execute
    return_value = self.execute_callable()
  File "/home/airflow/.local/lib/python3.6/site-packages/airflow/operators/python.py", line 161, in execute_callable
    return self.python_callable(*self.op_args, **self.op_kwargs)
TypeError: square() missing 1 required positional argument: 'x'
[2023-05-24 21:43:39,536] {taskinstance.py:1551} INFO - Marking task as FAILED. dag_id=python_square_operator, task_id=square, execution_date=20230523T120000, start_date=20230524T214339, end_date=20230524T214339
[2023-05-24 21:43:39,630] {local_task_job.py:151} INFO - Task exited with return code 1
